<?xml version="1.0" encoding="utf-8"?>
<!-- This URDF was automatically created by SolidWorks to URDF Exporter! Originally created by Stephen Brawner (brawner@gmail.com) 
     Commit Version: 1.6.0-4-g7f85cfe  Build Version: 1.6.7995.38578
     For more information, please see http://wiki.ros.org/sw_urdf_exporter -->
<robot
  name="Mars-Rover-URDF">
  <link
    name="base_link">
    <inertial>
      <origin
        xyz="0.0135427022776655 0.00237368886127913 0.0911475646666017"
        rpy="0 0 0" />
      <mass
        value="1.59483552" />
      <inertia
        ixx="0.01390300058104"
        ixy="8.34099127220805E-20"
        ixz="6.53256743568878E-20"
        iyy="0.0285974954758624"
        iyz="-7.98437892769272E-21"
        izz="0.0352539264984576" />
    </inertial>
    <visual>
      <origin
        xyz="0 0 0"
        rpy="0 0 0" />
      <geometry>
        <mesh
          filename="package://Mars-Rover-URDF/meshes/base_link.STL" />
      </geometry>
      <material
        name="">
        <color
          rgba="0.792156862745098 0.819607843137255 0.933333333333333 1" />
      </material>
    </visual>
    <collision>
      <origin
        xyz="0 0 0"
        rpy="0 0 0" />
      <geometry>
        <mesh
          filename="package://Mars-Rover-URDF/meshes/base_link.STL" />
      </geometry>
    </collision>
  </link>
  <link
    name="xbar_top_frame">
    <inertial>
      <origin
        xyz="0.00081149909692961 8.32667268468867E-16 0.1957"
        rpy="0 0 0" />
      <mass
        value="0.180967186857142" />
      <inertia
        ixx="0.000721536956668616"
        ixy="-2.7642978576952E-19"
        ixz="1.94373796744225E-19"
        iyy="0.00387959064131599"
        iyz="1.13512860712822E-19"
        izz="0.00459369904571847" />
    </inertial>
    <visual>
      <origin
        xyz="0 0 0"
        rpy="0 0 0" />
      <geometry>
        <mesh
          filename="package://Mars-Rover-URDF/meshes/xbar_top_frame.STL" />
      </geometry>
      <material
        name="">
        <color
          rgba="0.792156862745098 0.819607843137255 0.933333333333333 1" />
      </material>
    </visual>
    <collision>
      <origin
        xyz="0 0 0"
        rpy="0 0 0" />
      <geometry>
        <mesh
          filename="package://Mars-Rover-URDF/meshes/xbar_top_frame.STL" />
      </geometry>
    </collision>
  </link>
  <joint
    name="xbar_to_chassis_joint"
    type="fixed">
    <origin
      xyz="0.0176427022776656 -0.000626311138720845 0.0245815452491259"
      rpy="0 0 0" />
    <parent
      link="base_link" />
    <child
      link="xbar_top_frame" />
    <axis
      xyz="0 0 0" />
  </joint>
  <link
    name="rocker_to_frame_mount_left">
    <inertial>
      <origin
        xyz="-0.00189999920235706 -0.194277679658848 0.187230370865528"
        rpy="0 0 0" />
      <mass
        value="0.0178174846110633" />
      <inertia
        ixx="1.64411942078336E-06"
        ixy="-6.08082946915319E-14"
        ixz="2.61335301650268E-15"
        iyy="8.9149566286252E-06"
        iyz="1.87998295961392E-07"
        izz="8.30298452857927E-06" />
    </inertial>
    <visual>
      <origin
        xyz="0 0 0"
        rpy="0 0 0" />
      <geometry>
        <mesh
          filename="package://Mars-Rover-URDF/meshes/rocker_to_frame_mount_left.STL" />
      </geometry>
      <material
        name="">
        <color
          rgba="0.792156862745098 0.819607843137255 0.933333333333333 1" />
      </material>
    </visual>
    <collision>
      <origin
        xyz="0 0 0"
        rpy="0 0 0" />
      <geometry>
        <mesh
          filename="package://Mars-Rover-URDF/meshes/rocker_to_frame_mount_left.STL" />
      </geometry>
    </collision>
  </link>
  <joint
    name="rocker_to_frame_mount_left_joint"
    type="fixed">
    <origin
      xyz="0 0 0"
      rpy="0 0 3.14159265358979" />
    <parent
      link="xbar_top_frame" />
    <child
      link="rocker_to_frame_mount_left" />
    <axis
      xyz="0 0 0" />
  </joint>
  <link
    name="left_rocker">
    <inertial>
      <origin
        xyz="-0.14574 -0.014649 -0.03864"
        rpy="0 0 0" />
      <mass
        value="0.2386" />
      <inertia
        ixx="6.5639E-05"
        ixy="-3.2246E-07"
        ixz="6.396E-05"
        iyy="0.0011259"
        iyz="-1.2911E-06"
        izz="0.0010882" />
    </inertial>
    <visual>
      <origin
        xyz="0 0 0"
        rpy="0 0 0" />
      <geometry>
        <mesh
          filename="package://Mars-Rover-URDF/meshes/left_rocker.STL" />
      </geometry>
      <material
        name="">
        <color
          rgba="0.79216 0.81961 0.93333 1" />
      </material>
    </visual>
    <collision>
      <origin
        xyz="0 0 0"
        rpy="0 0 0" />
      <geometry>
        <mesh
          filename="package://Mars-Rover-URDF/meshes/left_rocker.STL" />
      </geometry>
    </collision>
  </link>
  <joint
    name="left_rocker_joint"
    type="continuous">
    <origin
      xyz="-0.0019 -0.2008 0.1732"
      rpy="0 0.20522 0" />
    <parent
      link="rocker_to_frame_mount_left" />
    <child
      link="left_rocker" />
    <axis
      xyz="0 1 0" />
  </joint>
</robot>